Traceback (most recent call last):
  File "B:\Major_Git\LangChain-models\RLHF\PPO\gpt_sentiment.py", line 68, in <module>
    ppo_trainer= PPOTrainer(config,
                ^^^^^^^^^^^^^^^^^^^
TypeError: PPOTrainer.__init__() got an unexpected keyword argument 'log_with'
